[2025-04-01 22:08:24] ERROR: 未捕获的异常:
Traceback (most recent call last):
  File "F:\Code\Local\Python\FtpAutoTasks\ftp-sender\src\ui\main_window.py", line 366, in open_config_dialog
    self.updateTaskList()
  File "F:\Code\Local\Python\FtpAutoTasks\ftp-sender\src\ui\main_window.py", line 266, in updateTaskList
    QTableWidgetItem(task.host),
                     ^^^^^^^^^
AttributeError: 'FTPTask' object has no attribute 'host'

[2025-04-01 22:08:53] ERROR: 未捕获的异常:
Traceback (most recent call last):
  File "F:\Code\Local\Python\FtpAutoTasks\ftp-sender\src\ui\main_window.py", line 324, in handle_exit
    self.stop_tasks()
  File "F:\Code\Local\Python\FtpAutoTasks\ftp-sender\src\ui\main_window.py", line 183, in stop_tasks
    self.updateTaskList()
  File "F:\Code\Local\Python\FtpAutoTasks\ftp-sender\src\ui\main_window.py", line 266, in updateTaskList
    QTableWidgetItem(task.host),
                     ^^^^^^^^^
AttributeError: 'FTPTask' object has no attribute 'host'

[2025-04-01 22:11:03] ERROR: 未捕获的异常:
Traceback (most recent call last):
  File "F:\Code\Local\Python\FtpAutoTasks\ftp-sender\src\ui\main_window.py", line 324, in handle_exit
    self.stop_tasks()
  File "F:\Code\Local\Python\FtpAutoTasks\ftp-sender\src\ui\main_window.py", line 183, in stop_tasks
    self.updateTaskList()
  File "F:\Code\Local\Python\FtpAutoTasks\ftp-sender\src\ui\main_window.py", line 266, in updateTaskList
    QTableWidgetItem(task.ftp_address),
                     ^^^^^^^^^
AttributeError: 'FTPTask' object has no attribute 'host'

[2025-04-01 22:34:49] ERROR: 未捕获的异常:
Traceback (most recent call last):
  File "F:\Code\Local\Python\FtpAutoTasks\ftp-sender\src\ui\main_window.py", line 409, in open_config_dialog
    self.task_manager.update_tasks(self.tasks)
  File "F:\Code\Local\Python\FtpAutoTasks\ftp-sender\src\core\task_manager.py", line 389, in update_tasks
    self.add_task(task)
  File "F:\Code\Local\Python\FtpAutoTasks\ftp-sender\src\core\task_manager.py", line 42, in add_task
    self.start_task(task.name)
  File "F:\Code\Local\Python\FtpAutoTasks\ftp-sender\src\core\task_manager.py", line 62, in start_task
    observer.schedule(event_handler, task.local_directory, recursive=False)
                                     ^^^^^^^^^^^^^^^^^^^^
AttributeError: 'FTPTask' object has no attribute 'local_directory'

[2025-04-01 22:49:21] ERROR: 未捕获的异常:
Traceback (most recent call last):
  File "F:\Code\Local\Python\FtpAutoTasks\ftp-sender\src\ui\config_dialog.py", line 121, in edit_task
    dialog = TaskEditDialog(task, self)
             ^^^^^^^^^^^^^^^^^^^^^^^^^^
  File "F:\Code\Local\Python\FtpAutoTasks\ftp-sender\src\ui\task_edit_dialog.py", line 13, in __init__
    self.load_task_data()
  File "F:\Code\Local\Python\FtpAutoTasks\ftp-sender\src\ui\task_edit_dialog.py", line 151, in load_task_data
    self.remote_dir_edit.setText(self.task.remote_directory)
                                 ^^^^^^^^^^^^^^^^^^^^^^^^^^
AttributeError: 'FTPTask' object has no attribute 'remote_directory'

[2025-04-01 22:49:22] ERROR: 未捕获的异常:
Traceback (most recent call last):
  File "F:\Code\Local\Python\FtpAutoTasks\ftp-sender\src\ui\config_dialog.py", line 121, in edit_task
    dialog = TaskEditDialog(task, self)
             ^^^^^^^^^^^^^^^^^^^^^^^^^^
  File "F:\Code\Local\Python\FtpAutoTasks\ftp-sender\src\ui\task_edit_dialog.py", line 13, in __init__
    self.load_task_data()
  File "F:\Code\Local\Python\FtpAutoTasks\ftp-sender\src\ui\task_edit_dialog.py", line 151, in load_task_data
    self.remote_dir_edit.setText(self.task.remote_directory)
                                 ^^^^^^^^^^^^^^^^^^^^^^^^^^
AttributeError: 'FTPTask' object has no attribute 'remote_directory'

[2025-04-01 22:49:23] ERROR: 未捕获的异常:
Traceback (most recent call last):
  File "F:\Code\Local\Python\FtpAutoTasks\ftp-sender\src\ui\config_dialog.py", line 121, in edit_task
    dialog = TaskEditDialog(task, self)
             ^^^^^^^^^^^^^^^^^^^^^^^^^^
  File "F:\Code\Local\Python\FtpAutoTasks\ftp-sender\src\ui\task_edit_dialog.py", line 13, in __init__
    self.load_task_data()
  File "F:\Code\Local\Python\FtpAutoTasks\ftp-sender\src\ui\task_edit_dialog.py", line 151, in load_task_data
    self.remote_dir_edit.setText(self.task.remote_directory)
                                 ^^^^^^^^^^^^^^^^^^^^^^^^^^
AttributeError: 'FTPTask' object has no attribute 'remote_directory'

[2025-04-01 22:49:25] ERROR: 未捕获的异常:
Traceback (most recent call last):
  File "F:\Code\Local\Python\FtpAutoTasks\ftp-sender\src\ui\config_dialog.py", line 121, in edit_task
    dialog = TaskEditDialog(task, self)
             ^^^^^^^^^^^^^^^^^^^^^^^^^^
  File "F:\Code\Local\Python\FtpAutoTasks\ftp-sender\src\ui\task_edit_dialog.py", line 13, in __init__
    self.load_task_data()
  File "F:\Code\Local\Python\FtpAutoTasks\ftp-sender\src\ui\task_edit_dialog.py", line 151, in load_task_data
    self.remote_dir_edit.setText(self.task.remote_directory)
                                 ^^^^^^^^^^^^^^^^^^^^^^^^^^
AttributeError: 'FTPTask' object has no attribute 'remote_directory'

[2025-04-01 22:49:26] ERROR: 未捕获的异常:
Traceback (most recent call last):
  File "F:\Code\Local\Python\FtpAutoTasks\ftp-sender\src\ui\config_dialog.py", line 121, in edit_task
    dialog = TaskEditDialog(task, self)
             ^^^^^^^^^^^^^^^^^^^^^^^^^^
  File "F:\Code\Local\Python\FtpAutoTasks\ftp-sender\src\ui\task_edit_dialog.py", line 13, in __init__
    self.load_task_data()
  File "F:\Code\Local\Python\FtpAutoTasks\ftp-sender\src\ui\task_edit_dialog.py", line 151, in load_task_data
    self.remote_dir_edit.setText(self.task.remote_directory)
                                 ^^^^^^^^^^^^^^^^^^^^^^^^^^
AttributeError: 'FTPTask' object has no attribute 'remote_directory'

[2025-04-01 22:49:27] ERROR: 未捕获的异常:
Traceback (most recent call last):
  File "F:\Code\Local\Python\FtpAutoTasks\ftp-sender\src\ui\config_dialog.py", line 121, in edit_task
    dialog = TaskEditDialog(task, self)
             ^^^^^^^^^^^^^^^^^^^^^^^^^^
  File "F:\Code\Local\Python\FtpAutoTasks\ftp-sender\src\ui\task_edit_dialog.py", line 13, in __init__
    self.load_task_data()
  File "F:\Code\Local\Python\FtpAutoTasks\ftp-sender\src\ui\task_edit_dialog.py", line 151, in load_task_data
    self.remote_dir_edit.setText(self.task.remote_directory)
                                 ^^^^^^^^^^^^^^^^^^^^^^^^^^
AttributeError: 'FTPTask' object has no attribute 'remote_directory'

[2025-04-01 22:49:28] ERROR: 未捕获的异常:
Traceback (most recent call last):
  File "F:\Code\Local\Python\FtpAutoTasks\ftp-sender\src\ui\config_dialog.py", line 121, in edit_task
    dialog = TaskEditDialog(task, self)
             ^^^^^^^^^^^^^^^^^^^^^^^^^^
  File "F:\Code\Local\Python\FtpAutoTasks\ftp-sender\src\ui\task_edit_dialog.py", line 13, in __init__
    self.load_task_data()
  File "F:\Code\Local\Python\FtpAutoTasks\ftp-sender\src\ui\task_edit_dialog.py", line 151, in load_task_data
    self.remote_dir_edit.setText(self.task.remote_directory)
                                 ^^^^^^^^^^^^^^^^^^^^^^^^^^
AttributeError: 'FTPTask' object has no attribute 'remote_directory'

[2025-04-01 22:49:29] ERROR: 未捕获的异常:
Traceback (most recent call last):
  File "F:\Code\Local\Python\FtpAutoTasks\ftp-sender\src\ui\config_dialog.py", line 121, in edit_task
    dialog = TaskEditDialog(task, self)
             ^^^^^^^^^^^^^^^^^^^^^^^^^^
  File "F:\Code\Local\Python\FtpAutoTasks\ftp-sender\src\ui\task_edit_dialog.py", line 13, in __init__
    self.load_task_data()
  File "F:\Code\Local\Python\FtpAutoTasks\ftp-sender\src\ui\task_edit_dialog.py", line 151, in load_task_data
    self.remote_dir_edit.setText(self.task.remote_directory)
                                 ^^^^^^^^^^^^^^^^^^^^^^^^^^
AttributeError: 'FTPTask' object has no attribute 'remote_directory'

[2025-04-01 22:49:32] ERROR: 未捕获的异常:
Traceback (most recent call last):
  File "F:\Code\Local\Python\FtpAutoTasks\ftp-sender\src\ui\config_dialog.py", line 121, in edit_task
    dialog = TaskEditDialog(task, self)
             ^^^^^^^^^^^^^^^^^^^^^^^^^^
  File "F:\Code\Local\Python\FtpAutoTasks\ftp-sender\src\ui\task_edit_dialog.py", line 13, in __init__
    self.load_task_data()
  File "F:\Code\Local\Python\FtpAutoTasks\ftp-sender\src\ui\task_edit_dialog.py", line 151, in load_task_data
    self.remote_dir_edit.setText(self.task.remote_directory)
                                 ^^^^^^^^^^^^^^^^^^^^^^^^^^
AttributeError: 'FTPTask' object has no attribute 'remote_directory'

[2025-04-01 22:49:33] ERROR: 未捕获的异常:
Traceback (most recent call last):
  File "F:\Code\Local\Python\FtpAutoTasks\ftp-sender\src\ui\config_dialog.py", line 121, in edit_task
    dialog = TaskEditDialog(task, self)
             ^^^^^^^^^^^^^^^^^^^^^^^^^^
  File "F:\Code\Local\Python\FtpAutoTasks\ftp-sender\src\ui\task_edit_dialog.py", line 13, in __init__
    self.load_task_data()
  File "F:\Code\Local\Python\FtpAutoTasks\ftp-sender\src\ui\task_edit_dialog.py", line 151, in load_task_data
    self.remote_dir_edit.setText(self.task.remote_directory)
                                 ^^^^^^^^^^^^^^^^^^^^^^^^^^
AttributeError: 'FTPTask' object has no attribute 'remote_directory'

[2025-04-01 22:49:34] ERROR: 未捕获的异常:
Traceback (most recent call last):
  File "F:\Code\Local\Python\FtpAutoTasks\ftp-sender\src\ui\config_dialog.py", line 121, in edit_task
    dialog = TaskEditDialog(task, self)
             ^^^^^^^^^^^^^^^^^^^^^^^^^^
  File "F:\Code\Local\Python\FtpAutoTasks\ftp-sender\src\ui\task_edit_dialog.py", line 13, in __init__
    self.load_task_data()
  File "F:\Code\Local\Python\FtpAutoTasks\ftp-sender\src\ui\task_edit_dialog.py", line 151, in load_task_data
    self.remote_dir_edit.setText(self.task.remote_directory)
                                 ^^^^^^^^^^^^^^^^^^^^^^^^^^
AttributeError: 'FTPTask' object has no attribute 'remote_directory'

[2025-04-01 22:49:34] ERROR: 未捕获的异常:
Traceback (most recent call last):
  File "F:\Code\Local\Python\FtpAutoTasks\ftp-sender\src\ui\config_dialog.py", line 121, in edit_task
    dialog = TaskEditDialog(task, self)
             ^^^^^^^^^^^^^^^^^^^^^^^^^^
  File "F:\Code\Local\Python\FtpAutoTasks\ftp-sender\src\ui\task_edit_dialog.py", line 13, in __init__
    self.load_task_data()
  File "F:\Code\Local\Python\FtpAutoTasks\ftp-sender\src\ui\task_edit_dialog.py", line 151, in load_task_data
    self.remote_dir_edit.setText(self.task.remote_directory)
                                 ^^^^^^^^^^^^^^^^^^^^^^^^^^
AttributeError: 'FTPTask' object has no attribute 'remote_directory'

[2025-04-01 22:49:34] ERROR: 未捕获的异常:
Traceback (most recent call last):
  File "F:\Code\Local\Python\FtpAutoTasks\ftp-sender\src\ui\config_dialog.py", line 121, in edit_task
    dialog = TaskEditDialog(task, self)
             ^^^^^^^^^^^^^^^^^^^^^^^^^^
  File "F:\Code\Local\Python\FtpAutoTasks\ftp-sender\src\ui\task_edit_dialog.py", line 13, in __init__
    self.load_task_data()
  File "F:\Code\Local\Python\FtpAutoTasks\ftp-sender\src\ui\task_edit_dialog.py", line 151, in load_task_data
    self.remote_dir_edit.setText(self.task.remote_directory)
                                 ^^^^^^^^^^^^^^^^^^^^^^^^^^
AttributeError: 'FTPTask' object has no attribute 'remote_directory'

[2025-04-01 22:49:35] ERROR: 未捕获的异常:
Traceback (most recent call last):
  File "F:\Code\Local\Python\FtpAutoTasks\ftp-sender\src\ui\config_dialog.py", line 121, in edit_task
    dialog = TaskEditDialog(task, self)
             ^^^^^^^^^^^^^^^^^^^^^^^^^^
  File "F:\Code\Local\Python\FtpAutoTasks\ftp-sender\src\ui\task_edit_dialog.py", line 13, in __init__
    self.load_task_data()
  File "F:\Code\Local\Python\FtpAutoTasks\ftp-sender\src\ui\task_edit_dialog.py", line 151, in load_task_data
    self.remote_dir_edit.setText(self.task.remote_directory)
                                 ^^^^^^^^^^^^^^^^^^^^^^^^^^
AttributeError: 'FTPTask' object has no attribute 'remote_directory'

[2025-04-01 22:53:14] ERROR: 未捕获的异常:
Traceback (most recent call last):
  File "F:\Code\Local\Python\FtpAutoTasks\ftp-sender\src\ui\main_window.py", line 323, in on_task_double_clicked
    self.edit_task(QTableWidgetItem(task_name))
  File "F:\Code\Local\Python\FtpAutoTasks\ftp-sender\src\ui\main_window.py", line 220, in edit_task
    dialog.load_task(task)
    ^^^^^^^^^^^^^^^^
AttributeError: 'ConfigDialog' object has no attribute 'load_task'

[2025-04-01 22:53:15] ERROR: 未捕获的异常:
Traceback (most recent call last):
  File "F:\Code\Local\Python\FtpAutoTasks\ftp-sender\src\ui\main_window.py", line 323, in on_task_double_clicked
    self.edit_task(QTableWidgetItem(task_name))
  File "F:\Code\Local\Python\FtpAutoTasks\ftp-sender\src\ui\main_window.py", line 220, in edit_task
    dialog.load_task(task)
    ^^^^^^^^^^^^^^^^
AttributeError: 'ConfigDialog' object has no attribute 'load_task'

[2025-04-01 22:53:15] ERROR: 未捕获的异常:
Traceback (most recent call last):
  File "F:\Code\Local\Python\FtpAutoTasks\ftp-sender\src\ui\main_window.py", line 323, in on_task_double_clicked
    self.edit_task(QTableWidgetItem(task_name))
  File "F:\Code\Local\Python\FtpAutoTasks\ftp-sender\src\ui\main_window.py", line 220, in edit_task
    dialog.load_task(task)
    ^^^^^^^^^^^^^^^^
AttributeError: 'ConfigDialog' object has no attribute 'load_task'

[2025-04-01 22:53:17] ERROR: 未捕获的异常:
Traceback (most recent call last):
  File "F:\Code\Local\Python\FtpAutoTasks\ftp-sender\src\ui\main_window.py", line 323, in on_task_double_clicked
    self.edit_task(QTableWidgetItem(task_name))
  File "F:\Code\Local\Python\FtpAutoTasks\ftp-sender\src\ui\main_window.py", line 220, in edit_task
    dialog.load_task(task)
    ^^^^^^^^^^^^^^^^
AttributeError: 'ConfigDialog' object has no attribute 'load_task'

[2025-04-01 22:53:17] ERROR: 未捕获的异常:
Traceback (most recent call last):
  File "F:\Code\Local\Python\FtpAutoTasks\ftp-sender\src\ui\main_window.py", line 323, in on_task_double_clicked
    self.edit_task(QTableWidgetItem(task_name))
  File "F:\Code\Local\Python\FtpAutoTasks\ftp-sender\src\ui\main_window.py", line 220, in edit_task
    dialog.load_task(task)
    ^^^^^^^^^^^^^^^^
AttributeError: 'ConfigDialog' object has no attribute 'load_task'

[2025-04-01 22:53:18] ERROR: 未捕获的异常:
Traceback (most recent call last):
  File "F:\Code\Local\Python\FtpAutoTasks\ftp-sender\src\ui\main_window.py", line 323, in on_task_double_clicked
    self.edit_task(QTableWidgetItem(task_name))
  File "F:\Code\Local\Python\FtpAutoTasks\ftp-sender\src\ui\main_window.py", line 220, in edit_task
    dialog.load_task(task)
    ^^^^^^^^^^^^^^^^
AttributeError: 'ConfigDialog' object has no attribute 'load_task'

[2025-04-01 22:53:18] ERROR: 未捕获的异常:
Traceback (most recent call last):
  File "F:\Code\Local\Python\FtpAutoTasks\ftp-sender\src\ui\main_window.py", line 323, in on_task_double_clicked
    self.edit_task(QTableWidgetItem(task_name))
  File "F:\Code\Local\Python\FtpAutoTasks\ftp-sender\src\ui\main_window.py", line 220, in edit_task
    dialog.load_task(task)
    ^^^^^^^^^^^^^^^^
AttributeError: 'ConfigDialog' object has no attribute 'load_task'

[2025-04-01 22:53:19] ERROR: 未捕获的异常:
Traceback (most recent call last):
  File "F:\Code\Local\Python\FtpAutoTasks\ftp-sender\src\ui\main_window.py", line 323, in on_task_double_clicked
    self.edit_task(QTableWidgetItem(task_name))
  File "F:\Code\Local\Python\FtpAutoTasks\ftp-sender\src\ui\main_window.py", line 220, in edit_task
    dialog.load_task(task)
    ^^^^^^^^^^^^^^^^
AttributeError: 'ConfigDialog' object has no attribute 'load_task'

[2025-04-01 23:22:23] ERROR: 未捕获的异常:
Traceback (most recent call last):
  File "F:\Code\Local\Python\FtpAutoTasks\ftp-sender\src\ui\main_window.py", line 330, in on_task_double_clicked
    self.edit_task(QTableWidgetItem(task_name))
  File "F:\Code\Local\Python\FtpAutoTasks\ftp-sender\src\ui\main_window.py", line 227, in edit_task
    dialog.load_task(task)
    ^^^^^^^^^^^^^^^^
AttributeError: 'ConfigDialog' object has no attribute 'load_task'

[2025-04-01 23:26:01] ERROR: 未捕获的异常:
Traceback (most recent call last):
  File "F:\Code\Local\Python\FtpAutoTasks\ftp-sender\src\ui\main_window.py", line 330, in on_task_double_clicked
    self.edit_task(QTableWidgetItem(task_name))
  File "F:\Code\Local\Python\FtpAutoTasks\ftp-sender\src\ui\main_window.py", line 227, in edit_task
    dialog.load_task(task)
    ^^^^^^^^^^^^^^^^
AttributeError: 'ConfigDialog' object has no attribute 'load_task'

[2025-04-01 23:26:07] ERROR: 未捕获的异常:
Traceback (most recent call last):
  File "F:\Code\Local\Python\FtpAutoTasks\ftp-sender\src\ui\main_window.py", line 330, in on_task_double_clicked
    self.edit_task(QTableWidgetItem(task_name))
  File "F:\Code\Local\Python\FtpAutoTasks\ftp-sender\src\ui\main_window.py", line 227, in edit_task
    dialog.load_task(task)
    ^^^^^^^^^^^^^^^^
AttributeError: 'ConfigDialog' object has no attribute 'load_task'

[2025-04-01 23:26:56] ERROR: 未捕获的异常:
Traceback (most recent call last):
  File "F:\Code\Local\Python\FtpAutoTasks\ftp-sender\src\ui\main_window.py", line 296, in on_task_double_clicked
    self.edit_task(QTableWidgetItem(task_name))
    ^^^^^^^^^^^^^^
AttributeError: 'MainWindow' object has no attribute 'edit_task'

